[2021-12-13 14:22:50,116] {taskinstance.py:1035} INFO - Dependencies all met for <TaskInstance: cpp_workflow.connect_to_database manual__2021-12-13T14:22:38.228977+00:00 [queued]>
[2021-12-13 14:22:50,132] {taskinstance.py:1035} INFO - Dependencies all met for <TaskInstance: cpp_workflow.connect_to_database manual__2021-12-13T14:22:38.228977+00:00 [queued]>
[2021-12-13 14:22:50,133] {taskinstance.py:1241} INFO - 
--------------------------------------------------------------------------------
[2021-12-13 14:22:50,133] {taskinstance.py:1242} INFO - Starting attempt 1 of 1
[2021-12-13 14:22:50,134] {taskinstance.py:1243} INFO - 
--------------------------------------------------------------------------------
[2021-12-13 14:22:50,150] {taskinstance.py:1262} INFO - Executing <Task(PythonOperator): connect_to_database> on 2021-12-13 14:22:38.228977+00:00
[2021-12-13 14:22:50,158] {standard_task_runner.py:52} INFO - Started process 9088 to run task
[2021-12-13 14:22:50,164] {standard_task_runner.py:76} INFO - Running: ['***', 'tasks', 'run', 'cpp_workflow', 'connect_to_database', 'manual__2021-12-13T14:22:38.228977+00:00', '--job-id', '1224', '--raw', '--subdir', 'DAGS_FOLDER/first_dag.py', '--cfg-path', '/tmp/tmp5yk8cozj', '--error-file', '/tmp/tmpfy4hjm3m']
[2021-12-13 14:22:50,166] {standard_task_runner.py:77} INFO - Job 1224: Subtask connect_to_database
[2021-12-13 14:22:50,264] {logging_mixin.py:109} INFO - Running <TaskInstance: cpp_workflow.connect_to_database manual__2021-12-13T14:22:38.228977+00:00 [running]> on host 218df5ddc363
[2021-12-13 14:22:50,352] {taskinstance.py:1429} INFO - Exporting the following env vars:
AIRFLOW_CTX_DAG_OWNER=***
AIRFLOW_CTX_DAG_ID=cpp_workflow
AIRFLOW_CTX_TASK_ID=connect_to_database
AIRFLOW_CTX_EXECUTION_DATE=2021-12-13T14:22:38.228977+00:00
AIRFLOW_CTX_DAG_RUN_ID=manual__2021-12-13T14:22:38.228977+00:00
[2021-12-13 14:22:50,535] {logging_mixin.py:109} INFO - You're connected to database
[2021-12-13 14:22:55,895] {logging_mixin.py:109} INFO - Error while connecting to the database 2055: Lost connection to MySQL server at 'studmysql01.fhict.local:3306', system error: 9 Bad file descriptor
[2021-12-13 14:22:55,896] {python.py:152} INFO - Done. Returned value was: None
[2021-12-13 14:22:55,909] {taskinstance.py:1280} INFO - Marking task as SUCCESS. dag_id=cpp_workflow, task_id=connect_to_database, execution_date=20211213T142238, start_date=20211213T142250, end_date=20211213T142255
[2021-12-13 14:22:55,930] {local_task_job.py:154} INFO - Task exited with return code 0
[2021-12-13 14:22:55,959] {local_task_job.py:264} INFO - 0 downstream tasks scheduled from follow-on schedule check
