[2021-12-13 14:26:48,347] {taskinstance.py:1035} INFO - Dependencies all met for <TaskInstance: cpp_workflow.connect_to_database manual__2021-12-13T14:26:36.003384+00:00 [queued]>
[2021-12-13 14:26:48,364] {taskinstance.py:1035} INFO - Dependencies all met for <TaskInstance: cpp_workflow.connect_to_database manual__2021-12-13T14:26:36.003384+00:00 [queued]>
[2021-12-13 14:26:48,365] {taskinstance.py:1241} INFO - 
--------------------------------------------------------------------------------
[2021-12-13 14:26:48,366] {taskinstance.py:1242} INFO - Starting attempt 1 of 1
[2021-12-13 14:26:48,368] {taskinstance.py:1243} INFO - 
--------------------------------------------------------------------------------
[2021-12-13 14:26:48,384] {taskinstance.py:1262} INFO - Executing <Task(PythonOperator): connect_to_database> on 2021-12-13 14:26:36.003384+00:00
[2021-12-13 14:26:48,390] {standard_task_runner.py:52} INFO - Started process 9319 to run task
[2021-12-13 14:26:48,395] {standard_task_runner.py:76} INFO - Running: ['***', 'tasks', 'run', 'cpp_workflow', 'connect_to_database', 'manual__2021-12-13T14:26:36.003384+00:00', '--job-id', '1240', '--raw', '--subdir', 'DAGS_FOLDER/first_dag.py', '--cfg-path', '/tmp/tmp91bv666z', '--error-file', '/tmp/tmplq5np5t4']
[2021-12-13 14:26:48,397] {standard_task_runner.py:77} INFO - Job 1240: Subtask connect_to_database
[2021-12-13 14:26:48,454] {logging_mixin.py:109} INFO - Running <TaskInstance: cpp_workflow.connect_to_database manual__2021-12-13T14:26:36.003384+00:00 [running]> on host 218df5ddc363
[2021-12-13 14:26:48,509] {taskinstance.py:1429} INFO - Exporting the following env vars:
AIRFLOW_CTX_DAG_OWNER=***
AIRFLOW_CTX_DAG_ID=cpp_workflow
AIRFLOW_CTX_TASK_ID=connect_to_database
AIRFLOW_CTX_EXECUTION_DATE=2021-12-13T14:26:36.003384+00:00
AIRFLOW_CTX_DAG_RUN_ID=manual__2021-12-13T14:26:36.003384+00:00
[2021-12-13 14:26:48,655] {logging_mixin.py:109} INFO - You're connected to database
[2021-12-13 14:26:54,229] {logging_mixin.py:109} INFO - Error while connecting to the database 2055: Lost connection to MySQL server at 'studmysql01.fhict.local:3306', system error: 9 Bad file descriptor
[2021-12-13 14:26:54,230] {python.py:152} INFO - Done. Returned value was: None
[2021-12-13 14:26:54,244] {taskinstance.py:1280} INFO - Marking task as SUCCESS. dag_id=cpp_workflow, task_id=connect_to_database, execution_date=20211213T142636, start_date=20211213T142648, end_date=20211213T142654
[2021-12-13 14:26:54,297] {local_task_job.py:154} INFO - Task exited with return code 0
[2021-12-13 14:26:54,325] {local_task_job.py:264} INFO - 0 downstream tasks scheduled from follow-on schedule check
