[2021-12-13 13:32:59,340] {taskinstance.py:1035} INFO - Dependencies all met for <TaskInstance: cpp_workflow.connect_to_database manual__2021-12-13T13:32:48.265269+00:00 [queued]>
[2021-12-13 13:32:59,353] {taskinstance.py:1035} INFO - Dependencies all met for <TaskInstance: cpp_workflow.connect_to_database manual__2021-12-13T13:32:48.265269+00:00 [queued]>
[2021-12-13 13:32:59,354] {taskinstance.py:1241} INFO - 
--------------------------------------------------------------------------------
[2021-12-13 13:32:59,354] {taskinstance.py:1242} INFO - Starting attempt 1 of 1
[2021-12-13 13:32:59,355] {taskinstance.py:1243} INFO - 
--------------------------------------------------------------------------------
[2021-12-13 13:32:59,371] {taskinstance.py:1262} INFO - Executing <Task(PythonOperator): connect_to_database> on 2021-12-13 13:32:48.265269+00:00
[2021-12-13 13:32:59,378] {standard_task_runner.py:52} INFO - Started process 6637 to run task
[2021-12-13 13:32:59,383] {standard_task_runner.py:76} INFO - Running: ['***', 'tasks', 'run', 'cpp_workflow', 'connect_to_database', 'manual__2021-12-13T13:32:48.265269+00:00', '--job-id', '1130', '--raw', '--subdir', 'DAGS_FOLDER/first_dag.py', '--cfg-path', '/tmp/tmpu1tz8y70', '--error-file', '/tmp/tmppjq0g1bj']
[2021-12-13 13:32:59,384] {standard_task_runner.py:77} INFO - Job 1130: Subtask connect_to_database
[2021-12-13 13:32:59,440] {logging_mixin.py:109} INFO - Running <TaskInstance: cpp_workflow.connect_to_database manual__2021-12-13T13:32:48.265269+00:00 [running]> on host 218df5ddc363
[2021-12-13 13:32:59,519] {taskinstance.py:1429} INFO - Exporting the following env vars:
AIRFLOW_CTX_DAG_OWNER=***
AIRFLOW_CTX_DAG_ID=cpp_workflow
AIRFLOW_CTX_TASK_ID=connect_to_database
AIRFLOW_CTX_EXECUTION_DATE=2021-12-13T13:32:48.265269+00:00
AIRFLOW_CTX_DAG_RUN_ID=manual__2021-12-13T13:32:48.265269+00:00
[2021-12-13 13:32:59,707] {logging_mixin.py:109} INFO - You're connected to database
[2021-12-13 13:33:03,676] {logging_mixin.py:109} INFO - Error while connecting to the database Not all parameters were used in the SQL statement
[2021-12-13 13:33:03,676] {python.py:152} INFO - Done. Returned value was: None
[2021-12-13 13:33:03,690] {taskinstance.py:1280} INFO - Marking task as SUCCESS. dag_id=cpp_workflow, task_id=connect_to_database, execution_date=20211213T133248, start_date=20211213T133259, end_date=20211213T133303
[2021-12-13 13:33:03,746] {local_task_job.py:154} INFO - Task exited with return code 0
[2021-12-13 13:33:03,774] {local_task_job.py:264} INFO - 0 downstream tasks scheduled from follow-on schedule check
